Workbook

Sheet Dashboard
A1: Dashboard financiero - Asís PerSe
A3: Proyecto | B3: Asís PerSe | C3: Ubicación | D3: Providencia, Guadalajara | E3: Desarrollador | F3: PerSe Capital
A4: Inversión total | B4: =Control!B8 -> 81898223 | C4: Tasa anual fija | D4: =Control!B22 -> 0.1825 | E4: TIR deuda anualizada | F4: =Control!B22 -> 0.1825
A5: Estudios | B5: =Control!B9 -> 38 | C5: Ocupación base | D5: =Control!B32 -> 0.7 | E5: Ingreso anual base | F5: =Control!B36 -> 13214880
A8: Estructura de capital | B8: Monto | D8: Indicador de mercado | E8: Asís PerSe | F8: Mercado/Zona
A9: =Control!A15 -> Deuda senior | B9: =Control!B15 -> 27350000 | D9: Costo por noche | E9: =Control!E16 -> 1350 | F9: =Control!F16 -> 801
A10: =Control!A16 -> Capital del desarrollador | B10: =Control!B16 -> 27091223 | D10: Ocupación | E10: =Control!E17 -> 0.7 | F10: =Control!F17 -> 0.68
A11: =Control!A17 -> Preventa | B11: =Control!B17 -> 27457000 | D11: Ingreso mensual | E11: =Control!E18 -> 28980 | F11: =Control!F18 -> 16618
D12: Ingreso anual | E12: =Control!E19 -> 347760 | F12: =Control!F19 -> 199498
A14: Resumen modelo de venta de unidades - Asís PerSe
A15: MAR anual | B15: =Venta_Proyecto!$B$29 -> 0.12 | D15: VPN @ MAR 12% | E15: =Venta_Proyecto!$G$10 -> 15275260
A16: TIR anualizada | B16: =Venta_Proyecto!$G$12 -> 0.63501448 | D16: Mes objetivo | E16: =Venta_Proyecto!$G$13 -> No alcanza
A17: Mes deuda liquidada | B17: =Venta_Proyecto!$G$14 -> No se liquida | D17: Decisión | E17: =Venta_Proyecto!$G$15 -> VIABLE

Sheet Control
A1: Modelo financiero preliminar - Asís PerSe
A3: Proyecto | B3: Asís PerSe
A4: Ubicación | B4: C. Asís 776, Italia Providencia, Guadalajara, Jalisco
A5: Desarrollador | B5: PerSe Capital
A7: Datos del proyecto | D7: Escenarios de operación
A8: Inversión total | B8: 81898223 | D8: Escenario | E8: Tarifa por noche | F8: Ocupación | G8: Costo operativo
A9: Número de estudios | B9: 38 | D9: Optimista | E9: 1450 | F9: 0.78 | G9: 0.32
A10: Participaciones totales | B10: 85 | D10: Base | E10: 1350 | F10: 0.7 | G10: 0.35
A11: Participaciones vendidas | B11: 34 | D11: Conservador | E11: 1200 | F11: 0.58 | G11: 0.39
A12: Avance de obra | B12: 0.42
A14: Estructura de capital | D14: Mercado y venta
A15: Deuda senior | B15: 27350000 | D15: Concepto | E15: Asís PerSe | F15: Mercado/Zona | G15: Unidad
A16: Capital del desarrollador | B16: 27091223 | D16: Costo por noche | E16: 1350 | F16: 801 | G16: MXN
A17: Preventa | B17: 27457000 | D17: Ocupación | E17: 0.7 | F17: 0.68 | G17: %
A18: Suma de fuentes | B18: =SUM(B15:B17) -> 81898223 | D18: Ingreso mensual por habitación | E18: 28980 | F18: 16618 | G18: MXN
A19: Diferencia vs inversión total | B19: =B18-B8 -> 0 | D19: Ingreso anual por habitación | E19: 347760 | F19: 199498 | G19: MXN
D20: Precio por m² | E20: 75097 | F20: 66730 | G20: MXN/m²
A21: Condiciones de deuda / briq.mx
A22: Tasa anual fija | B22: 0.1825
A23: Plazo de financiamiento (meses) | B23: 30
A24: Pago de intereses | B24: Trimestral
A25: Comisión briq.mx capital | B25: 0.01
A26: Comisión briq.mx intereses | B26: 0.01
A27: Valor garantía actual | B27: 52875668
A28: Garantía / crédito | B28: =B27/B15 -> 1.9332968
A30: Supuestos operativos
A31: Tarifa por noche base | B31: 1350
A32: Ocupación base | B32: 0.7
A33: Ingreso mensual por habitación | B33: 28980
A34: Ingreso anual por habitación | B34: =B33*12 -> 347760
A35: Número de estudios | B35: =B9 -> 38
A36: Ingreso anual total base | B36: =B34*B35 -> 13214880
A37: Crecimiento anual tarifa | B37: 0.04
A38: Costo operativo sobre ingresos | B38: 0.35
A39: Impuesto sobre utilidad | B39: 0.3
A40: Cap rate terminal | B40: 0.09
A41: Tasa de descuento proyecto | B41: 0.14

Sheet Supuestos_Trimestrales
A1: Supuestos trimestrales de construcción y financiamiento
A3: Concepto | B3: Q1 | C3: Q2 | D3: Q3 | E3: Q4 | F3: Q5 | G3: Q6 | H3: Q7 | I3: Q8 | J3: Q9 | K3: Q10 | L3: Q11 | M3: Q12
A4: Año | B4: 2025 | C4: 2025 | D4: 2025 | E4: 2025 | F4: 2026 | G4: 2026 | H4: 2026 | I4: 2026 | J4: 2027 | K4: 2027 | L4: 2027 | M4: 2027
A5: Inicio periodo | B5: 45658 | C5: 45748 | D5: 45839 | E5: 45931 | F5: 46023 | G5: 46113 | H5: 46204 | I5: 46296 | J5: 46388 | K5: 46478 | L5: 46569 | M5: 46661
A6: Fin periodo | B6: 45747 | C6: 45838 | D6: 45930 | E6: 46022 | F6: 46112 | G6: 46203 | H6: 46295 | I6: 46387 | J6: 46477 | K6: 46568 | L6: 46660 | M6: 46752
A7: Días operación | B7: 90 | C7: 91 | D7: 92 | E7: 92 | F7: 90 | G7: 91 | H7: 92 | I7: 92 | J7: 90 | K7: 91 | L7: 92 | M7: 92
A8: Días del año | B8: 365 | C8: 365 | D8: 365 | E8: 365 | F8: 365 | G8: 365 | H8: 365 | I8: 365 | J8: 365 | K8: 365 | L8: 365 | M8: 365
A9: No. de periodo | B9: 1 | C9: 2 | D9: 3 | E9: 4 | F9: 5 | G9: 6 | H9: 7 | I9: 8 | J9: 9 | K9: 10 | L9: 11 | M9: 12
A10: Bloque | B10: Bloque 1 - Anticipo 30% | C10: Bloque 2 - 70% restante / 11 | D10: Bloque 2 - 70% restante / 11 | E10: Bloque 2 - 70% restante / 11 | F10: Bloque 2 - 70% restante / 11 | G10: Bloque 2 - 70% restante / 11 | H10: Bloque 2 - 70% restante / 11 | I10: Bloque 2 - 70% restante / 11 | J10: Bloque 2 - 70% restante / 11 | K10: Bloque 2 - 70% restante / 11 | L10: Bloque 2 - 70% restante / 11 | M10: Bloque 3 - 70% restante / 11 + reserva 6 meses
A11: Programa de construcción / requerimiento | B11: =IF(B9=1,30%,70%/11) -> 0.3 | C11: =IF(C9=1,30%,70%/11) -> 0.063636364 | D11: =IF(D9=1,30%,70%/11) -> 0.063636364 | E11: =IF(E9=1,30%,70%/11) -> 0.063636364 | F11: =IF(F9=1,30%,70%/11) -> 0.063636364 | G11: =IF(G9=1,30%,70%/11) -> 0.063636364 | H11: =IF(H9=1,30%,70%/11) -> 0.063636364 | I11: =IF(I9=1,30%,70%/11) -> 0.063636364 | ... M11: =IF(M9=1,30%,70%/11) -> 0.063636364
A12: Requerimiento del proyecto | B12: =Control!$B$8*B11 -> 24569467 | C12: =Control!$B$8*C11 -> 5211705.1 | D12: =Control!$B$8*D11 -> 5211705.1 | E12: =Control!$B$8*E11 -> 5211705.1 | F12: =Control!$B$8*F11 -> 5211705.1 | G12: =Control!$B$8*G11 -> 5211705.1 | H12: =Control!$B$8*H11 -> 5211705.1 | I12: =Control!$B$8*I11 -> 5211705.1 | ... M12: =Control!$B$8*M11 -> 5211705.1
A13: Banco (70% del requerimiento) | B13: =B12*70% -> 17198627 | C13: =C12*70% -> 3648193.6 | D13: =D12*70% -> 3648193.6 | E13: =E12*70% -> 3648193.6 | F13: =F12*70% -> 3648193.6 | G13: =G12*70% -> 3648193.6 | H13: =H12*70% -> 3648193.6 | I13: =I12*70% -> 3648193.6 | ... M13: =M12*70% -> 3648193.6
A14: Inversionistas (30% del requerimiento) | B14: =B12*30% -> 7370840.1 | C14: =C12*30% -> 1563511.5 | D14: =D12*30% -> 1563511.5 | E14: =E12*30% -> 1563511.5 | F14: =F12*30% -> 1563511.5 | G14: =G12*30% -> 1563511.5 | H14: =H12*30% -> 1563511.5 | I14: =I12*30% -> 1563511.5 | ... M14: =M12*30% -> 1563511.5
A15: Fondo de reserva 6 meses | B15: =0 -> 0 | C15: =0 -> 0 | D15: =0 -> 0 | E15: =0 -> 0 | F15: =0 -> 0 | G15: =0 -> 0 | H15: =0 -> 0 | I15: =0 -> 0 | ... L15: =0 -> 0 | M15: =SUM(Deuda_60_Meses!$F$11:$F$16) -> 8479878.5
A16: Total requerido con reserva | B16: =B12+B15 -> 24569467 | C16: =C12+C15 -> 5211705.1 | D16: =D12+D15 -> 5211705.1 | E16: =E12+E15 -> 5211705.1 | F16: =F12+F15 -> 5211705.1 | G16: =G12+G15 -> 5211705.1 | H16: =H12+H15 -> 5211705.1 | I16: =I12+I15 -> 5211705.1 | ... M16: =M12+M15 -> 13691584
A18: Explicación del cálculo
A19: 1) Se toma como base la inversión total del proyecto registrada en Control!B8.
A20: 2) Q1 = 30% de la inversión total.
A21: 3) Q2 a Q12 = el 70% restante dividido entre 11 trimestres.
A22: 4) En cada trimestre: banco aporta 70% del requerimiento e inversionistas 30%. En Q12 se suma el fondo de reserva de 6 meses.

Sheet Deuda_60_Meses
A1: Calendario de amortización mensual - 60 meses
A3: Principal deuda senior | B3: =81898223*0.7 -> 57328756 | C3: 70% del banco
A4: Tasa anual para cálculo de clase | B4: =10% -> 0.1
A5: Plazo de amortización (meses) | B5: =60 -> 60
A6: Tasa mensual | B6: =B4/12 -> 0.0083333333
A7: Amortización mensual | B7: =B3/B5 -> 955479.27
A8: Fondo de reserva 6 meses | B8: =SUM(F11:F16) -> 8479878.5
A10: Mes | B10: Saldo inicial | C10: Interés | D10: Amortización | E10: Servicio de deuda | F10: Fondo reserva 6M | G10: Saldo insoluto | H10: Comentario
A11: 1 | B11: =IF(A11=1,$B$3,G10) -> 57328756 | C11: =B11*$B$6 -> 477739.63 | D11: =$B$7 -> 955479.27 | E11: =C11+D11 -> 1433218.9 | F11: =IF(A11<=6,E11,0) -> 1433218.9 | G11: =B11-D11 -> 56373277 | H11: ="Curva pareja: misma amortización mensual; interés baja conforme baja el saldo." -> Curva pareja: misma amortización mensual; interés baja conforme baja el saldo.
A12: 2 | B12: =IF(A12=1,$B$3,G11) -> 56373277 | C12: =B12*$B$6 -> 469777.31 | D12: =$B$7 -> 955479.27 | E12: =C12+D12 -> 1425256.6 | F12: =IF(A12<=6,E12,0) -> 1425256.6 | G12: =B12-D12 -> 55417798 | H12: ="Curva pareja: misma amortización mensual; interés baja conforme baja el saldo." -> Curva pareja: misma amortización mensual; interés baja conforme baja el saldo.
A13: 3 | B13: =IF(A13=1,$B$3,G12) -> 55417798 | C13: =B13*$B$6 -> 461814.98 | D13: =$B$7 -> 955479.27 | E13: =C13+D13 -> 1417294.2 | F13: =IF(A13<=6,E13,0) -> 1417294.2 | G13: =B13-D13 -> 54462318 | H13: ="Curva pareja: misma amortización mensual; interés baja conforme baja el saldo." -> Curva pareja: misma amortización mensual; interés baja conforme baja el saldo.
A14: 4 | B14: =IF(A14=1,$B$3,G13) -> 54462318 | C14: =B14*$B$6 -> 453852.65 | D14: =$B$7 -> 955479.27 | E14: =C14+D14 -> 1409331.9 | F14: =IF(A14<=6,E14,0) -> 1409331.9 | G14: =B14-D14 -> 53506839 | H14: ="Curva pareja: misma amortización mensual; interés baja conforme baja el saldo." -> Curva pareja: misma amortización mensual; interés baja conforme baja el saldo.
A15: 5 | B15: =IF(A15=1,$B$3,G14) -> 53506839 | C15: =B15*$B$6 -> 445890.33 | D15: =$B$7 -> 955479.27 | E15: =C15+D15 -> 1401369.6 | F15: =IF(A15<=6,E15,0) -> 1401369.6 | G15: =B15-D15 -> 52551360 | H15: ="Curva pareja: misma amortización mensual; interés baja conforme baja el saldo." -> Curva pareja: misma amortización mensual; interés baja conforme baja el saldo.
A16: 6 | B16: =IF(A16=1,$B$3,G15) -> 52551360 | C16: =B16*$B$6 -> 437928 | D16: =$B$7 -> 955479.27 | E16: =C16+D16 -> 1393407.3 | F16: =IF(A16<=6,E16,0) -> 1393407.3 | G16: =B16-D16 -> 51595880 | H16: ="Curva pareja: misma amortización mensual; interés baja conforme baja el saldo." -> Curva pareja: misma amortización mensual; interés baja conforme baja el saldo.
A17: 7 | B17: =IF(A17=1,$B$3,G16) -> 51595880 | C17: =B17*$B$6 -> 429965.67 | D17: =$B$7 -> 955479.27 | E17: =C17+D17 -> 1385444.9 | F17: =IF(A17<=6,E17,0) -> 0 | G17: =B17-D17 -> 50640401 | H17: ="Curva pareja: misma amortización mensual; interés baja conforme baja el saldo." -> Curva pareja: misma amortización mensual; interés baja conforme baja el saldo.
A18: 8 | B18: =IF(A18=1,$B$3,G17) -> 50640401 | C18: =B18*$B$6 -> 422003.34 | D18: =$B$7 -> 955479.27 | E18: =C18+D18 -> 1377482.6 | F18: =IF(A18<=6,E18,0) -> 0 | G18: =B18-D18 -> 49684922 | H18: ="Curva pareja: misma amortización mensual; interés baja conforme baja el saldo." -> Curva pareja: misma amortización mensual; interés baja conforme baja el saldo.
A19: 9 | B19: =IF(A19=1,$B$3,G18) -> 49684922 | C19: =B19*$B$6 -> 414041.02 | D19: =$B$7 -> 955479.27 | E19: =C19+D19 -> 1369520.3 | F19: =IF(A19<=6,E19,0) -> 0 | G19: =B19-D19 -> 48729443 | H19: ="Curva pareja: misma amortización mensual; interés baja conforme baja el saldo." -> Curva pareja: misma amortización mensual; interés baja conforme baja el saldo.
A20: 10 | B20: =IF(A20=1,$B$3,G19) -> 48729443 | C20: =B20*$B$6 -> 406078.69 | D20: =$B$7 -> 955479.27 | E20: =C20+D20 -> 1361558 | F20: =IF(A20<=6,E20,0) -> 0 | G20: =B20-D20 -> 47773963 | H20: ="Curva pareja: misma amortización mensual; interés baja conforme baja el saldo." -> Curva pareja: misma amortización mensual; interés baja conforme baja el saldo.
A21: 11 | B21: =IF(A21=1,$B$3,G20) -> 47773963 | C21: =B21*$B$6 -> 398116.36 | D21: =$B$7 -> 955479.27 | E21: =C21+D21 -> 1353595.6 | F21: =IF(A21<=6,E21,0) -> 0 | G21: =B21-D21 -> 46818484 | H21: ="Curva pareja: misma amortización mensual; interés baja conforme baja el saldo." -> Curva pareja: misma amortización mensual; interés baja conforme baja el saldo.
A22: 12 | B22: =IF(A22=1,$B$3,G21) -> 46818484 | C22: =B22*$B$6 -> 390154.03 | D22: =$B$7 -> 955479.27 | E22: =C22+D22 -> 1345633.3 | F22: =IF(A22<=6,E22,0) -> 0 | G22: =B22-D22 -> 45863005 | H22: ="Curva pareja: misma amortización mensual; interés baja conforme baja el saldo." -> Curva pareja: misma amortización mensual; interés baja conforme baja el saldo.
... A65: 55 | B65: =IF(A65=1,$B$3,G64) -> 5732875.6 | C65: =B65*$B$6 -> 47773.963 | D65: =$B$7 -> 955479.27 | E65: =C65+D65 -> 1003253.2 | F65: =IF(A65<=6,E65,0) -> 0 | G65: =B65-D65 -> 4777396.3 | H65: ="Curva pareja: misma amortización mensual; interés baja conforme baja el saldo." -> Curva pareja: misma amortización mensual; interés baja conforme baja el saldo.
A66: 56 | B66: =IF(A66=1,$B$3,G65) -> 4777396.3 | C66: =B66*$B$6 -> 39811.636 | D66: =$B$7 -> 955479.27 | E66: =C66+D66 -> 995290.9 | F66: =IF(A66<=6,E66,0) -> 0 | G66: =B66-D66 -> 3821917.1 | H66: ="Curva pareja: misma amortización mensual; interés baja conforme baja el saldo." -> Curva pareja: misma amortización mensual; interés baja conforme baja el saldo. | K66: =IF(A11=1,$B$3,G10) -> 57328756
A67: 57 | B67: =IF(A67=1,$B$3,G66) -> 3821917.1 | C67: =B67*$B$6 -> 31849.309 | D67: =$B$7 -> 955479.27 | E67: =C67+D67 -> 987328.58 | F67: =IF(A67<=6,E67,0) -> 0 | G67: =B67-D67 -> 2866437.8 | H67: ="Curva pareja: misma amortización mensual; interés baja conforme baja el saldo." -> Curva pareja: misma amortización mensual; interés baja conforme baja el saldo.
A68: 58 | B68: =IF(A68=1,$B$3,G67) -> 2866437.8 | C68: =B68*$B$6 -> 23886.982 | D68: =$B$7 -> 955479.27 | E68: =C68+D68 -> 979366.25 | F68: =IF(A68<=6,E68,0) -> 0 | G68: =B68-D68 -> 1910958.5 | H68: ="Curva pareja: misma amortización mensual; interés baja conforme baja el saldo." -> Curva pareja: misma amortización mensual; interés baja conforme baja el saldo.
A69: 59 | B69: =IF(A69=1,$B$3,G68) -> 1910958.5 | C69: =B69*$B$6 -> 15924.654 | D69: =$B$7 -> 955479.27 | E69: =C69+D69 -> 971403.92 | F69: =IF(A69<=6,E69,0) -> 0 | G69: =B69-D69 -> 955479.27 | H69: ="Curva pareja: misma amortización mensual; interés baja conforme baja el saldo." -> Curva pareja: misma amortización mensual; interés baja conforme baja el saldo.
A70: 60 | B70: =IF(A70=1,$B$3,G69) -> 955479.27 | C70: =B70*$B$6 -> 7962.3272 | D70: =$B$7 -> 955479.27 | E70: =C70+D70 -> 963441.6 | F70: =IF(A70<=6,E70,0) -> 0 | G70: =B70-D70 -> 4.2142347e-08 | H70: ="Curva pareja: misma amortización mensual; interés baja conforme baja el saldo." -> Curva pareja: misma amortización mensual; interés baja conforme baja el saldo.

Sheet Venta_Proyecto
A1: Modelo de venta de unidades y cascada de pagos - Asís PerSe
A2: Modelo ajustado con los datos del proyecto: inversión total, 38 estudios y financiamiento 70% banco / 30% inversionistas. Las celdas en azul son supuestos editables.
A4: Supuestos principales | F4: Resumen de viabilidad | J4: Cómo se interpreta la cascada
A5: Costo total del proyecto | B5: =Control!$B$8 -> 81898223 | C5: MXN | D5: Ligado a Control!B8 | F5: Ventas totales generadas | G5: =SUM(E40:E69) -> 1.2796597e+08 | H5: Suma de ingresos del calendario | J5: 1 | K5: El banco no se paga de forma fija cada mes; si no hay ventas, el interés se capitaliza y aumenta el saldo de la deuda.
A6: Deuda banco 70% | B6: =B5*70% -> 57328756 | C6: MXN | D6: 70% de la inversión total | F6: Unidades vendidas | G6: =SUM(B40:B69) -> 38 | H6: Debe coincidir con los 38 estudios | J6: 2 | K6: Cuando se vende una unidad, el ingreso entra a la cascada: ISR/impuestos → gastos administrativos → agencia inmobiliaria → oficinas → amortización al banco.
A7: Inversión socios 30% | B7: =B5*30% -> 24569467 | C7: MXN | D7: 30% de la inversión total | F7: Saldo final de deuda | G7: =P69 -> 0 | H7: Si es 0, el banco quedó liquidado | J7: 3 | K7: La amortización al banco toma el efectivo disponible hasta liquidar el saldo de la deuda más los intereses generados del mes.
A8: Número de unidades / estudios | B8: =Control!$B$9 -> 38 | C8: unidades | D8: Ligado a Control!B9 | F8: Flujo libre total | G8: =SUM(O40:O69) -> 46101921 | H8: Suma de flujo libre mensual | J8: 4 | K8: El flujo libre de caja aparece cuando, después de la cascada, queda dinero sobrante para los inversionistas.
A9: Multiplicador ventas/costo | B9: 1.5625 | C9: x | D9: Supuesto: conserva proporción del ejemplo del maestro $25M / $16M | F9: Valor presente de flujos | G9: =NPV($B$30,O40:O69) -> 39844727 | H9: VP de flujos libres con MAR mensual | J9: 5 | K9: La viabilidad se revisa con VPN usando MAR anual de 12% y con TIR. Si TIR anualizada > MAR y VPN > 0, el proyecto se acepta.
A10: Valor total de ventas estimado | B10: =B5*B9 -> 1.2796597e+08 | C10: MXN | D10: Costo total x multiplicador | F10: VPN @ MAR 12% | G10: =G9-$B$7 -> 15275260 | H10: VP de flujos - inversión de socios | J10: Fuente | K10: Datos tomados del Excel del proyecto Asís PerSe. El precio de venta se estimó manteniendo la relación ventas/costo del ejemplo del pizarrón: 25/16 = 1.5625x.
A11: Precio de venta por unidad | B11: =B10/B8 -> 3367525.6 | C11: MXN/unidad | D11: Ventas totales / estudios | F11: TIR mensual | G11: =IFERROR(IRR(B77:AF77),0) -> 0.041821863 | H11: TIR del flujo al inversionista
A12: Agencia inmobiliaria | B12: 0.04 | C12: % venta | D12: Equivale al ejemplo: $100,000 / $2,500,000 = 4% | F12: TIR anualizada | G12: =(1+G11)^12-1 -> 0.63501448 | H12: Equivalente anual compuesto
A13: Agencia por unidad | B13: =B11*B12 -> 134701.02 | C13: MXN/unidad | D13: Precio por unidad x comisión | F13: Mes objetivo con flujo libre | G13: =IFERROR(_xludf.MINIFS(A40:A69,O40:O69,">0"),"No alcanza") -> No alcanza | H13: Primer mes con flujo libre positivo
A14: Gasto administrativo | B14: 0.03125 | C14: % costo | D14: Equivale al ejemplo: $500,000 / $16,000,000 = 3.125% | F14: Mes deuda liquidada | G14: =IFERROR(_xludf.MINIFS(A40:A69,P40:P69,"<=1"),"No se liquida") -> No se liquida | H14: Primer mes con saldo final <= 1
A15: Gasto administrativo total | B15: =B5*B14 -> 2559319.5 | C15: MXN | D15: Costo total x % administrativo | F15: Decisión | G15: =IF(AND(G10>0,G12>$B$29),"VIABLE","NO VIABLE") -> VIABLE | H15: VIABLE si VPN > 0 y TIR anual > MAR anual
A16: Meses con gasto administrativo | B16: =ROUNDUP(B8/B17,0) -> 19 | C16: meses | D16: Estimado con venta objetivo mensual
A17: Venta mensual objetivo | B17: 2 | C17: unidades/mes | D17: Editable; se usa para estimar meses de gasto
A18: Gasto administrativo mensual | B18: =B15/B16 -> 134701.02 | C18: MXN/mes | D18: Gasto administrativo total / meses
A19: Oficinas mensual | B19: 0 | C19: MXN/mes | D19: Editable si se desea separar oficinas
A20: Meses con gasto de oficinas | B20: =B16 -> 19 | C20: meses | D20: Igual a meses administrativos
A21: Total oficinas | B21: =B19*B20 -> 0 | C21: MXN | D21: Oficinas mensual x meses
A22: Gastos adicionales totales | B22: =B13*B8+B15+B21 -> 7677958.4 | C22: MXN | D22: Agencia + admin + oficinas
A23: Utilidad gravable antes de ISR | B23: =B10-(B5+B22) -> 38389792 | C23: MXN | D23: Ventas - costo - gastos adicionales
A24: ISR / impuestos | B24: 0.3 | C24: % | D24: Supuesto del maestro
A25: ISR total estimado | B25: =MAX(B23*B24,0) -> 11516938 | C25: MXN | D25: Utilidad gravable x ISR
A26: ISR por unidad | B26: =B25/B8 -> 303077.31 | C26: MXN/unidad | D26: ISR total / número de unidades
A27: Tasa banco anual | B27: =Control!$B$22 -> 0.1825 | C27: % anual | D27: Ligado a Control!B22 del proyecto
A28: Tasa banco mensual | B28: =B27/12 -> 0.015208333 | C28: % mensual | D28: Tasa anual / 12
A29: MAR anual | B29: 0.12 | C29: % anual | D29: Rendimiento mínimo aceptable solicitado
A30: MAR mensual efectiva | B30: =(1+B29)^(1/12)-1 -> 0.0094887929 | C30: % mensual | D30: (1 + MAR anual)^(1/12)-1
A31: Meses del modelo | B31: =Control!$B$23 -> 30 | C31: meses | D31: Ligado a Control!B23
A36: Calendario mensual editable de ventas y cascada de pagos
A37: En la columna B puedes cambiar las unidades vendidas por mes. El escenario base vende 2 unidades por mes hasta colocar los 38 estudios.
A39: Mes | B39: Unidades vendidas (editable) | C39: Unidades acumuladas | D39: Unidades restantes | E39: Ingreso por ventas | F39: Impuestos / ISR | G39: Gastos admin | H39: Agencia inmobiliaria | I39: Oficinas | J39: Disponible antes banco | K39: Saldo deuda inicial | L39: Interés generado | M39: Deuda antes pago | N39: Amortización banco | O39: Flujo libre de caja | P39: Saldo deuda final | Q39: Déficit a financiar | R39: Comentario | T39: Mes | U39: Ingreso ventas | V39: Flujo libre | W39: Saldo deuda final
A40: 1 | B40: 2 | C40: =SUM($B$40:B40) -> 2 | D40: =MAX($B$8-C40,0) -> 36 | E40: =B40*$B$11 -> 6735051.2 | F40: =B40*$B$26 -> 606154.61 | G40: =IF(A40<=$B$16,$B$18,0) -> 134701.02 | H40: =B40*$B$13 -> 269402.05 | I40: =IF(A40<=$B$20,$B$19,0) -> 0 | J40: =E40-F40-G40-H40-I40 -> 5724793.5 | K40: =IF(A40=1,$B$6,P39) -> 57328756 | L40: =K40*$B$28 -> 871874.83 | M40: =K40+L40 -> 58200631 | N40: =MIN(MAX(J40,0),M40) -> 5724793.5 | O40: =J40-N40 -> 0 | P40: =M40-N40 -> 52475837 | Q40: =MAX(-J40,0) -> 0 | R40: =IF(Q40>0,"Sin caja: usar reserva/capital",IF(P40>1,"Se sigue pagando banco","Flujo libre")) -> Se sigue pagando banco | T40: =A40 -> 1 | U40: =E40 -> 6735051.2 | V40: =O40 -> 0 | W40: =P40 -> 52475837
A41: 2 | B41: 2 | C41: =SUM($B$40:B41) -> 4 | D41: =MAX($B$8-C41,0) -> 34 | E41: =B41*$B$11 -> 6735051.2 | F41: =B41*$B$26 -> 606154.61 | G41: =IF(A41<=$B$16,$B$18,0) -> 134701.02 | H41: =B41*$B$13 -> 269402.05 | I41: =IF(A41<=$B$20,$B$19,0) -> 0 | J41: =E41-F41-G41-H41-I41 -> 5724793.5 | K41: =IF(A41=1,$B$6,P40) -> 52475837 | L41: =K41*$B$28 -> 798070.03 | M41: =K41+L41 -> 53273907 | N41: =MIN(MAX(J41,0),M41) -> 5724793.5 | O41: =J41-N41 -> 0 | P41: =M41-N41 -> 47549114 | Q41: =MAX(-J41,0) -> 0 | R41: =IF(Q41>0,"Sin caja: usar reserva/capital",IF(P41>1,"Se sigue pagando banco","Flujo libre")) -> Se sigue pagando banco | T41: =A41 -> 2 | U41: =E41 -> 6735051.2 | V41: =O41 -> 0 | W41: =P41 -> 47549114
A42: 3 | B42: 2 | C42: =SUM($B$40:B42) -> 6 | D42: =MAX($B$8-C42,0) -> 32 | E42: =B42*$B$11 -> 6735051.2 | F42: =B42*$B$26 -> 606154.61 | G42: =IF(A42<=$B$16,$B$18,0) -> 134701.02 | H42: =B42*$B$13 -> 269402.05 | I42: =IF(A42<=$B$20,$B$19,0) -> 0 | J42: =E42-F42-G42-H42-I42 -> 5724793.5 | K42: =IF(A42=1,$B$6,P41) -> 47549114 | L42: =K42*$B$28 -> 723142.77 | M42: =K42+L42 -> 48272257 | N42: =MIN(MAX(J42,0),M42) -> 5724793.5 | O42: =J42-N42 -> 0 | P42: =M42-N42 -> 42547463 | Q42: =MAX(-J42,0) -> 0 | R42: =IF(Q42>0,"Sin caja: usar reserva/capital",IF(P42>1,"Se sigue pagando banco","Flujo libre")) -> Se sigue pagando banco | T42: =A42 -> 3 | U42: =E42 -> 6735051.2 | V42: =O42 -> 0 | W42: =P42 -> 42547463
A43: 4 | B43: 2 | C43: =SUM($B$40:B43) -> 8 | D43: =MAX($B$8-C43,0) -> 30 | E43: =B43*$B$11 -> 6735051.2 | F43: =B43*$B$26 -> 606154.61 | G43: =IF(A43<=$B$16,$B$18,0) -> 134701.02 | H43: =B43*$B$13 -> 269402.05 | I43: =IF(A43<=$B$20,$B$19,0) -> 0 | J43: =E43-F43-G43-H43-I43 -> 5724793.5 | K43: =IF(A43=1,$B$6,P42) -> 42547463 | L43: =K43*$B$28 -> 647076 | M43: =K43+L43 -> 43194539 | N43: =MIN(MAX(J43,0),M43) -> 5724793.5 | O43: =J43-N43 -> 0 | P43: =M43-N43 -> 37469746 | Q43: =MAX(-J43,0) -> 0 | R43: =IF(Q43>0,"Sin caja: usar reserva/capital",IF(P43>1,"Se sigue pagando banco","Flujo libre")) -> Se sigue pagando banco | T43: =A43 -> 4 | U43: =E43 -> 6735051.2 | V43: =O43 -> 0 | W43: =P43 -> 37469746
A44: 5 | B44: 2 | C44: =SUM($B$40:B44) -> 10 | D44: =MAX($B$8-C44,0) -> 28 | E44: =B44*$B$11 -> 6735051.2 | F44: =B44*$B$26 -> 606154.61 | G44: =IF(A44<=$B$16,$B$18,0) -> 134701.02 | H44: =B44*$B$13 -> 269402.05 | I44: =IF(A44<=$B$20,$B$19,0) -> 0 | J44: =E44-F44-G44-H44-I44 -> 5724793.5 | K44: =IF(A44=1,$B$6,P43) -> 37469746 | L44: =K44*$B$28 -> 569852.38 | M44: =K44+L44 -> 38039598 | N44: =MIN(MAX(J44,0),M44) -> 5724793.5 | O44: =J44-N44 -> 0 | P44: =M44-N44 -> 32314804 | Q44: =MAX(-J44,0) -> 0 | R44: =IF(Q44>0,"Sin caja: usar reserva/capital",IF(P44>1,"Se sigue pagando banco","Flujo libre")) -> Se sigue pagando banco | T44: =A44 -> 5 | U44: =E44 -> 6735051.2 | V44: =O44 -> 0 | W44: =P44 -> 32314804
A45: 6 | B45: 2 | C45: =SUM($B$40:B45) -> 12 | D45: =MAX($B$8-C45,0) -> 26 | E45: =B45*$B$11 -> 6735051.2 | F45: =B45*$B$26 -> 606154.61 | G45: =IF(A45<=$B$16,$B$18,0) -> 134701.02 | H45: =B45*$B$13 -> 269402.05 | I45: =IF(A45<=$B$20,$B$19,0) -> 0 | J45: =E45-F45-G45-H45-I45 -> 5724793.5 | K45: =IF(A45=1,$B$6,P44) -> 32314804 | L45: =K45*$B$28 -> 491454.32 | M45: =K45+L45 -> 32806259 | N45: =MIN(MAX(J45,0),M45) -> 5724793.5 | O45: =J45-N45 -> 0 | P45: =M45-N45 -> 27081465 | Q45: =MAX(-J45,0) -> 0 | R45: =IF(Q45>0,"Sin caja: usar reserva/capital",IF(P45>1,"Se sigue pagando banco","Flujo libre")) -> Se sigue pagando banco | T45: =A45 -> 6 | U45: =E45 -> 6735051.2 | V45: =O45 -> 0 | W45: =P45 -> 27081465
A46: 7 | B46: 2 | C46: =SUM($B$40:B46) -> 14 | D46: =MAX($B$8-C46,0) -> 24 | E46: =B46*$B$11 -> 6735051.2 | F46: =B46*$B$26 -> 606154.61 | G46: =IF(A46<=$B$16,$B$18,0) -> 134701.02 | H46: =B46*$B$13 -> 269402.05 | I46: =IF(A46<=$B$20,$B$19,0) -> 0 | J46: =E46-F46-G46-H46-I46 -> 5724793.5 | K46: =IF(A46=1,$B$6,P45) -> 27081465 | L46: =K46*$B$28 -> 411863.95 | M46: =K46+L46 -> 27493329 | N46: =MIN(MAX(J46,0),M46) -> 5724793.5 | O46: =J46-N46 -> 0 | P46: =M46-N46 -> 21768536 | Q46: =MAX(-J46,0) -> 0 | R46: =IF(Q46>0,"Sin caja: usar reserva/capital",IF(P46>1,"Se sigue pagando banco","Flujo libre")) -> Se sigue pagando banco | T46: =A46 -> 7 | U46: =E46 -> 6735051.2 | V46: =O46 -> 0 | W46: =P46 -> 21768536
...
